Исключения в Java — это важная концепция, которая помогает разработчикам управлять ошибками и иными исключительными ситуациями в процессе выполнения программы. Сегодня я расскажу вам об этой теме.

**1. Введение в исключения**

Исключения (exceptions) — это события, которые возникают во время выполнения программы и нарушают нормальный ход её инструкций. В Java исключения обрабатываются с помощью специальных блоков кода, что позволяет программе обрабатывать ошибки более грациозно, без "падения".

**2. Иерархия исключений**

Все классы исключений наследуются от класса `Throwable`. Главные подклассы `Throwable` — это `Error` и `Exception`. `Error` используется для критических системных ошибок, от которых невозможно восстановиться. `Exception` — это исключение, которое может быть обработано приложением.

**3. Проверяемые и непроверяемые исключения**

Исключения в Java делятся на два типа:

- Проверяемые (checked exceptions): исключения, которые должны быть явно обработаны в коде или объявлены в сигнатуре метода.
- Непроверяемые (unchecked exceptions): исключения, обработка которых не требуется обязательно.

**4. Обработка исключений**

Для обработки исключений используются блоки `try`, `catch` и `finally`.

- `try`: код, который может вызвать исключение, помещается в блок `try`.
- `catch`: после блока `try` следует блок `catch`, где указывается тип исключения и код для его обработки.
- `finally`: блок `finally` выполняется всегда после `try/catch`, независимо от того, было ли исключение.

**5. Создание собственных исключений**

Вы также можете создавать собственные классы исключений, наследуясь от класса `Exception` или его подклассов.

**6. Практические примеры**

Давайте рассмотрим пример кода с обработкой исключений:


	public class ExceptionExample {
    	public static void main(String[] args) {
        	try {
            	int result = divide(10, 0);
            	System.out.println(result);
        	} catch (ArithmeticException e) {
            	System.out.println("Ошибка: " + e.getMessage());
        	} finally {
           	 System.out.println("Операция попытки деления завершена.");
       	 }
    	}

    public static int divide(int a, int b) {
        return a / b; // Это может вызвать ArithmeticException при b == 0
    	}
	}


В этом примере мы пытаемся выполнить деление на ноль, что вызовет `ArithmeticException`. Ошибка будет перехвачена и обработана в блоке `catch`, а блок `finally` гарантирует выполнение кода после попытки выполнения операции.

**7. Лучшие практики**

- Не используйте исключения для управления потоком программы.
- Не перехватывайте `Exception` или `Throwable`, так как это может привести к перехвату всех возможных исключений, даже тех, которые не должны обрабатываться.
- Всегда закрывайте ресурсы в блоке `finally` или используйте конструкцию try-with-resources.

**8. Try-with-resources**

Это конструкция, введённая в Java 7, позволяющая автоматически закрывать ресурсы, которые реализуют интерфейс `

AutoCloseable` или `Closeable`.

Пример:

```java
try (BufferedReader br = new BufferedReader(new FileReader("path/to/file.txt"))) {
    // Используем BufferedReader
} catch (IOException e) {
    // Обработка исключения IOException
}
```